Workbook

Sheet SUPUESTOS
A1: CADENA DE SUMINISTRO – DEPORTIVOS BOLIVIA S.R.L.
A2: Archivo de Cálculo – Supuestos y Parámetros Base | UCB – Trabajo Final de Asignatura
A4: Parámetro | B4: Nombre ref. | C4: Valor | D4: Unidad | E4: Nota
A5: GENERALES
A6: Tipo de cambio | B6: TCC | C6: 6.96 | D6: Bs/USD | E6: BCB oficial de venta
A7: Horizonte planificación | B7: HOR | C7: 6 | D7: meses
A8: Días calendario semestre | B8: DC | C8: 180 | D8: días
A9: Días operativos/mes | B9: DOM | C9: 26 | D9: días
A10: Días operativos semestre | B10: DOS | C10: 156 | D10: días
A11: CONTENEDOR
A12: Volumen útil 40' | B12: VOL_CONT | C12: 60 | D12: m³ | E12: Capacidad de planificación
A13: Volumen neto productos | B13: VOL_NETO | C13: 53.74 | D13: m³ | E13: Suma CBM tabla
A14: Incremento embalaje volumen | B14: INC_VOL | C14: 0.08 | D14: % | E14: Embalaje 2°/3°
A15: Volumen con embalaje | B15: VOL_EMB | C15: =B11*(1+B12) -> #VALUE! | D15: m³ | E15: =53.74×1.08 -> #ERROR!
A16: Utilización contenedor | B16: UTIL_CONT | C16: =B13/B9 -> #VALUE! | D16: %
A17: Peso neto total | B17: PESO_NETO | C17: 9457 | D17: kg | E17: Suma pesos
A18: Incremento peso embalaje | B18: INC_PESO | C18: 0.12 | D18: %
A19: Peso bruto total | B19: PESO_BRUTO | C19: =B16*(1+B17) -> #VALUE! | D19: kg | E19: =9457×1.12 -> #ERROR!
A20: IMPORTACIÓN
A21: FOB total (tabla T1) | B21: FOB_TOT | C21: =T1_PRODUCTOS!W23 | D21: USD | E21: Suma FOB tabla
A22: Flete marítimo 40' | B22: FLETE | C22: 3500 | D22: USD | E22: Ruta Panamá→Callao→Bolivia (ref. Maersk)
A23: Seguro (% FOB) | B23: SEG_PCT | C23: 0.007 | D23: % | E23: 0.70% del FOB
A24: Seguro monto | B24: SEG | C24: =B20*B19 -> #VALUE! | D24: USD | E24: =FOB×0.70% -> #ERROR!
A25: CIF | B25: CIF_VAL | C25: =B20+B21+B22 -> #VALUE! | D25: USD | E25: FOB+Flete+Seguro
A26: Gastos documentales | B26: GD | C26: 350 | D26: USD | E26: Por embarque
A27: Gastos portuarios | B27: GP | C27: 1200 | D27: USD | E27: Por contenedor
A28: Agencia despachante (% CIF) | B28: AG_PCT | C28: 0.008 | D28: % | E28: 0.80% CIF
A29: Agencia monto | B29: AG | C29: =MAX(B23*B26,300) -> #VALUE! | D29: USD | E29: mínimo 300 USD
A30: Transporte interno Cochabamba | B30: TRANSP | C30: 2200 | D30: USD | E30: Por contenedor
A31: Merma logística (% FOB) | B31: MERMA_PCT | C31: 0.01 | D31: % | E31: 1% FOB
A32: Merma monto | B32: MERMA | C32: =B20*B30 -> #VALUE! | D32: USD
A33: GA (Gravamen Arancelario) | B33: GA_PCT | C33: 0.1 | D33: % | E33: 10% sobre CIF
A34: GA monto | B34: GA | C34: =B23*B32 -> #VALUE! | D34: USD
A35: Base imponible | B35: BASE_IMP | C35: =B23+B33 -> #VALUE! | D35: USD | E35: CIF+GA
A36: IVA efectivo importación | B36: IVA_PCT | C36: 0.1494 | D36: % | E36: 14.94% sobre base imponible
A37: IVA monto | B37: IVA | C37: =B35*B34 -> #VALUE! | D37: USD
A38: Total tributos | B38: TRIB | C38: =B33+B36 -> #VALUE! | D38: USD | E38: GA+IVA
A39: COSTO TOTAL hasta almacén | B39: CT_USD | C39: =B20+B21+B22+B24+B25+B27+B28+B31+B37 -> #VALUE! | D39: USD
A40: Costo total en Bs | B40: CT_BS | C40: =B38*B4 -> #VALUE! | D40: Bs
A41: Multiplicador unitario | B41: MULT | C41: =B38/B20 -> #VALUE! | D41: factor | E41: CT/FOB
...

Sheet T1_PRODUCTOS
A1: TABLA 1 – LISTA OFICIAL DE MERCADERÍA | CBM, Pesos y Valores FOB
A2: Código | B2: Producto | C2: Categoría | D2: Cantidad Semestral | E2: Peso Unit. (kg) | F2: Vol. Unit. (m³) | G2: FOB Unit. (USD) | H2: CBM Total (m³) | I2: Peso Total (kg) | J2: Valor FOB Total (USD) | K2: Costo Unit. Almacén (Bs) | L2: Precio Venta Ref. (Bs)
A3: DSP-RUN-001 | B3: Zapatillas running | C3: Calzado | D3: 800 | E3: 0.9 | F3: 0.012 | G3: 18 | H3: =D3*F3 -> 9.6 | I3: =D3*E3 -> 720 | J3: =D3*G3 -> 14400 | K3: =G3*SUPUESTOS!$B$40*SUPUESTOS!$B$4 -> #VALUE! | L3: =K3/(1-0.45) -> #VALUE!
A4: DSP-TRN-002 | B4: Zapatillas training | C4: Calzado | D4: 500 | E4: 1 | F4: 0.013 | G4: 20 | H4: =D4*F4 -> 6.5 | I4: =D4*E4 -> 500 | J4: =D4*G4 -> 10000 | K4: =G4*SUPUESTOS!$B$40*SUPUESTOS!$B$4 -> #VALUE! | L4: =K4/(1-0.45) -> #VALUE!
A5: BAL-FUT-003 | B5: Balón fútbol Nº5 | C5: Dep. equipo | D5: 1000 | E5: 0.45 | F5: 0.003 | G5: 4.5 | H5: =D5*F5 -> 3 | I5: =D5*E5 -> 450 | J5: =D5*G5 -> 4500 | K5: =G5*SUPUESTOS!$B$40*SUPUESTOS!$B$4 -> #VALUE! | L5: =K5/(1-0.35) -> #VALUE!
A6: BAL-FUTS-004 | B6: Balón futsal | C6: Dep. equipo | D6: 700 | E6: 0.43 | F6: 0.0028 | G6: 4.2 | H6: =D6*F6 -> 1.96 | I6: =D6*E6 -> 301 | J6: =D6*G6 -> 2940 | K6: =G6*SUPUESTOS!$B$40*SUPUESTOS!$B$4 -> #VALUE! | L6: =K6/(1-0.35) -> #VALUE!
A7: BAL-BASK-005 | B7: Balón básquet | C7: Dep. equipo | D7: 600 | E7: 0.6 | F7: 0.004 | G7: 5.2 | H7: =D7*F7 -> 2.4 | I7: =D7*E7 -> 360 | J7: =D7*G7 -> 3120 | K7: =G7*SUPUESTOS!$B$40*SUPUESTOS!$B$4 -> #VALUE! | L7: =K7/(1-0.35) -> #VALUE!
A8: FIT-YOG-006 | B8: Mat yoga/fitness | C8: Fitness | D8: 800 | E8: 0.9 | F8: 0.011 | G8: 5.8 | H8: =D8*F8 -> 8.8 | I8: =D8*E8 -> 720 | J8: =D8*G8 -> 4640 | K8: =G8*SUPUESTOS!$B$40*SUPUESTOS!$B$4 -> #VALUE! | L8: =K8/(1-0.4) -> #VALUE!
A9: FIT-BAN-007 | B9: Set bandas resistencia | C9: Fitness | D9: 1200 | E9: 0.2 | F9: 0.0012 | G9: 1.8 | H9: =D9*F9 -> 1.44 | I9: =D9*E9 -> 240 | J9: =D9*G9 -> 2160 | K9: =G9*SUPUESTOS!$B$40*SUPUESTOS!$B$4 -> #VALUE! | L9: =K9/(1-0.4) -> #VALUE!
A10: FIT-ROP-008 | B10: Cuerda de salto | C10: Fitness | D10: 1000 | E10: 0.15 | F10: 0.0008 | G10: 1.2 | H10: =D10*F10 -> 0.8 | I10: =D10*E10 -> 150 | J10: =D10*G10 -> 1200 | K10: =G10*SUPUESTOS!$B$40*SUPUESTOS!$B$4 -> #VALUE! | L10: =K10/(1-0.4) -> #VALUE!
A11: FIT-DB2-009 | B11: Par mancuernas 2 kg | C11: Fitness | D11: 400 | E11: 4.3 | F11: 0.004 | G11: 4.8 | H11: =D11*F11 -> 1.6 | I11: =D11*E11 -> 1720 | J11: =D11*G11 -> 1920 | K11: =G11*SUPUESTOS!$B$40*SUPUESTOS!$B$4 -> #VALUE! | L11: =K11/(1-0.4) -> #VALUE!
A12: FIT-DB5-010 | B12: Par mancuernas 5 kg | C12: Fitness | D12: 250 | E12: 10.4 | F12: 0.006 | G12: 10.5 | H12: =D12*F12 -> 1.5 | I12: =D12*E12 -> 2600 | J12: =D12*G12 -> 2625 | K12: =G12*SUPUESTOS!$B$40*SUPUESTOS!$B$4 -> #VALUE! | L12: =K12/(1-0.4) -> #VALUE!
A13: ACC-GLO-011 | B13: Guantes de gimnasio | C13: Accesorios | D13: 900 | E13: 0.2 | F13: 0.001 | G13: 2.2 | H13: =D13*F13 -> 0.9 | I13: =D13*E13 -> 180 | J13: =D13*G13 -> 1980 | K13: =G13*SUPUESTOS!$B$40*SUPUESTOS!$B$4 -> #VALUE! | L13: =K13/(1-0.45) -> #VALUE!
A14: ACC-BAG-012 | B14: Mochila deportiva | C14: Accesorios | D14: 500 | E14: 0.65 | F14: 0.01 | G14: 6.5 | H14: =D14*F14 -> 5 | I14: =D14*E14 -> 325 | J14: =D14*G14 -> 3250 | K14: =G14*SUPUESTOS!$B$40*SUPUESTOS!$B$4 -> #VALUE! | L14: =K14/(1-0.45) -> #VALUE!
A15: ACC-BOT-013 | B15: Botella deportiva 750ml | C15: Accesorios | D15: 1000 | E15: 0.15 | F15: 0.002 | G15: 1.6 | H15: =D15*F15 -> 2 | I15: =D15*E15 -> 150 | J15: =D15*G15 -> 1600 | K15: =G15*SUPUESTOS!$B$40*SUPUESTOS!$B$4 -> #VALUE! | L15: =K15/(1-0.45) -> #VALUE!
A16: APP-JER-014 | B16: Polera dry-fit | C16: Indumentaria | D16: 1000 | E16: 0.18 | F16: 0.0015 | G16: 3.8 | H16: =D16*F16 -> 1.5 | I16: =D16*E16 -> 180 | J16: =D16*G16 -> 3800 | K16: =G16*SUPUESTOS!$B$40*SUPUESTOS!$B$4 -> #VALUE! | L16: =K16/(1-0.5) -> #VALUE!
A17: APP-SHO-015 | B17: Short deportivo | C17: Indumentaria | D17: 900 | E17: 0.15 | F17: 0.0012 | G17: 3 | H17: =D17*F17 -> 1.08 | I17: =D17*E17 -> 135 | J17: =D17*G17 -> 2700 | K17: =G17*SUPUESTOS!$B$40*SUPUESTOS!$B$4 -> #VALUE! | L17: =K17/(1-0.5) -> #VALUE!
A18: APP-LEG-016 | B18: Legging deportivo | C18: Indumentaria | D18: 700 | E18: 0.18 | F18: 0.0013 | G18: 4 | H18: =D18*F18 -> 0.91 | I18: =D18*E18 -> 126 | J18: =D18*G18 -> 2800 | K18: =G18*SUPUESTOS!$B$40*SUPUESTOS!$B$4 -> #VALUE! | L18: =K18/(1-0.5) -> #VALUE!
A19: APP-SOC-017 | B19: Pack medias deportivas | C19: Indumentaria | D19: 1500 | E19: 0.08 | F19: 0.0005 | G19: 0.8 | H19: =D19*F19 -> 0.75 | I19: =D19*E19 -> 120 | J19: =D19*G19 -> 1200 | K19: =G19*SUPUESTOS!$B$40*SUPUESTOS!$B$4 -> #VALUE! | L19: =K19/(1-0.5) -> #VALUE!
A20: ACC-CAP-018 | B20: Gorra deportiva | C20: Accesorios | D20: 800 | E20: 0.1 | F20: 0.001 | G20: 1.4 | H20: =D20*F20 -> 0.8 | I20: =D20*E20 -> 80 | J20: =D20*G20 -> 1120 | K20: =G20*SUPUESTOS!$B$40*SUPUESTOS!$B$4 -> #VALUE! | L20: =K20/(1-0.45) -> #VALUE!
A21: TEAM-CON-019 | B21: Set conos entrenamiento | C21: Dep. equipo | D21: 300 | E21: 0.75 | F21: 0.006 | G21: 3.5 | H21: =D21*F21 -> 1.8 | I21: =D21*E21 -> 225 | J21: =D21*G21 -> 1050 | K21: =G21*SUPUESTOS!$B$40*SUPUESTOS!$B$4 -> #VALUE! | L21: =K21/(1-0.35) -> #VALUE!
A22: TEAM-SHI-020 | B22: Par canilleras | C22: Dep. equipo | D22: 700 | E22: 0.25 | F22: 0.002 | G22: 2.1 | H22: =D22*F22 -> 1.4 | I22: =D22*E22 -> 175 | J22: =D22*G22 -> 1470 | K22: =G22*SUPUESTOS!$B$40*SUPUESTOS!$B$4 -> #VALUE! | L22: =K22/(1-0.35) -> #VALUE!
A23: TOTAL | D23: =SUM(D3:D22) -> 15550 | H23: =SUM(H3:H22) -> 53.74 | I23: =SUM(I3:I22) -> 9457 | J23: =SUM(J3:J22) -> 68475
A25: Notas: CBM Total = Cantidad × Vol. unitario | Peso Total = Cantidad × Peso unitario | Costo almacén = FOB × Multiplicador (96,621/68,475=1.411) × TCC 6.96 Bs/USD | Precio venta = Costo almacén / (1 – margen categoría)

Sheet T2_DEMANDA
A1: TABLA 2 – MATRIZ DE DEMANDA SEMESTRAL POR UBICACIÓN Y DISTRIBUCIÓN ONLINE
A2: Código | B2: Producto | C2: TOTAL | D2: Cochabamba | E2: La Paz | F2: Santa Cruz | G2: ONLINE total | H2: DISTRIBUCIÓN ONLINE POR DEPARTAMENTO
B3: Producto | C3: TOTAL | D3: Cochabamba | E3: La Paz | F3: Santa Cruz | G3: ONLINE total | H3: Tarija | I3: Chuquisaca | J3: Oruro | K3: Potosí | L3: Beni | M3: Pando | N3: Dem. Mensual | O3: Dem. Diaria
A4: DSP-RUN-001 | B4: Zapatillas running | C4: 800 | D4: 216 | E4: 192 | F4: 248 | G4: 144 | H4: =G4-ROUND(G4*0.23,0)-ROUND(G4*0.18,0)-ROUND(G4*0.15,0)-ROUND(G4*0.13,0)-ROUND(G4*0.07,0) -> 34 | I4: =ROUND(G4*0.23,0) -> 33 | J4: =ROUND(G4*0.18,0) -> 26 | K4: =ROUND(G4*0.15,0) -> 22 | L4: =ROUND(G4*0.13,0) -> 19 | M4: =ROUND(G4*0.07,0) -> 10 | N4: =C4/SUPUESTOS!$B$5 -> #DIV/0! | O4: =C4/SUPUESTOS!$B$7 -> #VALUE!
A5: DSP-TRN-002 | B5: Zapatillas training | C5: 500 | D5: 135 | E5: 120 | F5: 155 | G5: 90 | H5: =G5-ROUND(G5*0.23,0)-ROUND(G5*0.18,0)-ROUND(G5*0.15,0)-ROUND(G5*0.13,0)-ROUND(G5*0.07,0) -> 21 | I5: =ROUND(G5*0.23,0) -> 21 | J5: =ROUND(G5*0.18,0) -> 16 | K5: =ROUND(G5*0.15,0) -> 14 | L5: =ROUND(G5*0.13,0) -> 12 | M5: =ROUND(G5*0.07,0) -> 6 | N5: =C5/SUPUESTOS!$B$5 -> #DIV/0! | O5: =C5/SUPUESTOS!$B$7 -> #VALUE!
A6: BAL-FUT-003 | B6: Balón fútbol Nº5 | C6: 1000 | D6: 270 | E6: 240 | F6: 310 | G6: 180 | H6: =G6-ROUND(G6*0.23,0)-ROUND(G6*0.18,0)-ROUND(G6*0.15,0)-ROUND(G6*0.13,0)-ROUND(G6*0.07,0) -> 44 | I6: =ROUND(G6*0.23,0) -> 41 | J6: =ROUND(G6*0.18,0) -> 32 | K6: =ROUND(G6*0.15,0) -> 27 | L6: =ROUND(G6*0.13,0) -> 23 | M6: =ROUND(G6*0.07,0) -> 13 | N6: =C6/SUPUESTOS!$B$5 -> #DIV/0! | O6: =C6/SUPUESTOS!$B$7 -> #VALUE!
A7: BAL-FUTS-004 | B7: Balón futsal | C7: 700 | D7: 189 | E7: 168 | F7: 217 | G7: 126 | H7: =G7-ROUND(G7*0.23,0)-ROUND(G7*0.18,0)-ROUND(G7*0.15,0)-ROUND(G7*0.13,0)-ROUND(G7*0.07,0) -> 30 | I7: =ROUND(G7*0.23,0) -> 29 | J7: =ROUND(G7*0.18,0) -> 23 | K7: =ROUND(G7*0.15,0) -> 19 | L7: =ROUND(G7*0.13,0) -> 16 | M7: =ROUND(G7*0.07,0) -> 9 | N7: =C7/SUPUESTOS!$B$5 -> #DIV/0! | O7: =C7/SUPUESTOS!$B$7 -> #VALUE!
A8: BAL-BASK-005 | B8: Balón básquet | C8: 600 | D8: 162 | E8: 144 | F8: 186 | G8: 108 | H8: =G8-ROUND(G8*0.23,0)-ROUND(G8*0.18,0)-ROUND(G8*0.15,0)-ROUND(G8*0.13,0)-ROUND(G8*0.07,0) -> 26 | I8: =ROUND(G8*0.23,0) -> 25 | J8: =ROUND(G8*0.18,0) -> 19 | K8: =ROUND(G8*0.15,0) -> 16 | L8: =ROUND(G8*0.13,0) -> 14 | M8: =ROUND(G8*0.07,0) -> 8 | N8: =C8/SUPUESTOS!$B$5 -> #DIV/0! | O8: =C8/SUPUESTOS!$B$7 -> #VALUE!
A9: FIT-YOG-006 | B9: Mat yoga/fitness | C9: 800 | D9: 216 | E9: 192 | F9: 248 | G9: 144 | H9: =G9-ROUND(G9*0.23,0)-ROUND(G9*0.18,0)-ROUND(G9*0.15,0)-ROUND(G9*0.13,0)-ROUND(G9*0.07,0) -> 34 | I9: =ROUND(G9*0.23,0) -> 33 | J9: =ROUND(G9*0.18,0) -> 26 | K9: =ROUND(G9*0.15,0) -> 22 | L9: =ROUND(G9*0.13,0) -> 19 | M9: =ROUND(G9*0.07,0) -> 10 | N9: =C9/SUPUESTOS!$B$5 -> #DIV/0! | O9: =C9/SUPUESTOS!$B$7 -> #VALUE!
A10: FIT-BAN-007 | B10: Set bandas resistencia | C10: 1200 | D10: 324 | E10: 288 | F10: 372 | G10: 216 | H10: =G10-ROUND(G10*0.23,0)-ROUND(G10*0.18,0)-ROUND(G10*0.15,0)-ROUND(G10*0.13,0)-ROUND(G10*0.07,0) -> 52 | I10: =ROUND(G10*0.23,0) -> 50 | J10: =ROUND(G10*0.18,0) -> 39 | K10: =ROUND(G10*0.15,0) -> 32 | L10: =ROUND(G10*0.13,0) -> 28 | M10: =ROUND(G10*0.07,0) -> 15 | N10: =C10/SUPUESTOS!$B$5 -> #DIV/0! | O10: =C10/SUPUESTOS!$B$7 -> #VALUE!
A11: FIT-ROP-008 | B11: Cuerda de salto | C11: 1000 | D11: 270 | E11: 240 | F11: 310 | G11: 180 | H11: =G11-ROUND(G11*0.23,0)-ROUND(G11*0.18,0)-ROUND(G11*0.15,0)-ROUND(G11*0.13,0)-ROUND(G11*0.07,0) -> 44 | I11: =ROUND(G11*0.23,0) -> 41 | J11: =ROUND(G11*0.18,0) -> 32 | K11: =ROUND(G11*0.15,0) -> 27 | L11: =ROUND(G11*0.13,0) -> 23 | M11: =ROUND(G11*0.07,0) -> 13 | N11: =C11/SUPUESTOS!$B$5 -> #DIV/0! | O11: =C11/SUPUESTOS!$B$7 -> #VALUE!
A12: FIT-DB2-009 | B12: Par mancuernas 2 kg | C12: 400 | D12: 108 | E12: 96 | F12: 124 | G12: 72 | H12: =G12-ROUND(G12*0.23,0)-ROUND(G12*0.18,0)-ROUND(G12*0.15,0)-ROUND(G12*0.13,0)-ROUND(G12*0.07,0) -> 17 | I12: =ROUND(G12*0.23,0) -> 17 | J12: =ROUND(G12*0.18,0) -> 13 | K12: =ROUND(G12*0.15,0) -> 11 | L12: =ROUND(G12*0.13,0) -> 9 | M12: =ROUND(G12*0.07,0) -> 5 | N12: =C12/SUPUESTOS!$B$5 -> #DIV/0! | O12: =C12/SUPUESTOS!$B$7 -> #VALUE!
A13: FIT-DB5-010 | B13: Par mancuernas 5 kg | C13: 250 | D13: 68 | E13: 60 | F13: 77 | G13: 45 | H13: =G13-ROUND(G13*0.23,0)-ROUND(G13*0.18,0)-ROUND(G13*0.15,0)-ROUND(G13*0.13,0)-ROUND(G13*0.07,0) -> 11 | I13: =ROUND(G13*0.23,0) -> 10 | J13: =ROUND(G13*0.18,0) -> 8 | K13: =ROUND(G13*0.15,0) -> 7 | L13: =ROUND(G13*0.13,0) -> 6 | M13: =ROUND(G13*0.07,0) -> 3 | N13: =C13/SUPUESTOS!$B$5 -> #DIV/0! | O13: =C13/SUPUESTOS!$B$7 -> #VALUE!
A14: ACC-GLO-011 | B14: Guantes de gimnasio | C14: 900 | D14: 243 | E14: 216 | F14: 279 | G14: 162 | H14: =G14-ROUND(G14*0.23,0)-ROUND(G14*0.18,0)-ROUND(G14*0.15,0)-ROUND(G14*0.13,0)-ROUND(G14*0.07,0) -> 40 | I14: =ROUND(G14*0.23,0) -> 37 | J14: =ROUND(G14*0.18,0) -> 29 | K14: =ROUND(G14*0.15,0) -> 24 | L14: =ROUND(G14*0.13,0) -> 21 | M14: =ROUND(G14*0.07,0) -> 11 | N14: =C14/SUPUESTOS!$B$5 -> #DIV/0! | O14: =C14/SUPUESTOS!$B$7 -> #VALUE!
A15: ACC-BAG-012 | B15: Mochila deportiva | C15: 500 | D15: 135 | E15: 120 | F15: 155 | G15: 90 | H15: =G15-ROUND(G15*0.23,0)-ROUND(G15*0.18,0)-ROUND(G15*0.15,0)-ROUND(G15*0.13,0)-ROUND(G15*0.07,0) -> 21 | I15: =ROUND(G15*0.23,0) -> 21 | J15: =ROUND(G15*0.18,0) -> 16 | K15: =ROUND(G15*0.15,0) -> 14 | L15: =ROUND(G15*0.13,0) -> 12 | M15: =ROUND(G15*0.07,0) -> 6 | N15: =C15/SUPUESTOS!$B$5 -> #DIV/0! | O15: =C15/SUPUESTOS!$B$7 -> #VALUE!
... A23: TEAM-SHI-020 | B23: Par canilleras | C23: 700 | D23: 189 | E23: 168 | F23: 217 | G23: 126 | H23: =G23-ROUND(G23*0.23,0)-ROUND(G23*0.18,0)-ROUND(G23*0.15,0)-ROUND(G23*0.13,0)-ROUND(G23*0.07,0) -> 30 | I23: =ROUND(G23*0.23,0) -> 29 | J23: =ROUND(G23*0.18,0) -> 23 | K23: =ROUND(G23*0.15,0) -> 19 | L23: =ROUND(G23*0.13,0) -> 16 | M23: =ROUND(G23*0.07,0) -> 9 | N23: =C23/SUPUESTOS!$B$5 -> #DIV/0! | O23: =C23/SUPUESTOS!$B$7 -> #VALUE!
A24: TOTAL | C24: =SUM(C4:C23) -> 15550 | D24: =SUM(D4:D23) -> 4199 | E24: =SUM(E4:E23) -> 3732 | F24: =SUM(F4:F23) -> 4820 | G24: =SUM(G4:G23) -> 2799 | H24: =SUM(H4:H23) -> 673 | I24: =SUM(I4:I23) -> 642 | J24: =SUM(J4:J23) -> 503 | ... O24: =SUM(O4:O23) -> #VALUE!
A27: PARTICIPACIÓN CANAL ONLINE POR DEPARTAMENTO
A28: Departamento | B28: Participación | C28: Unidades estimadas
A29: Tarija | B29: 0.24 | C29: =G24*B29 -> 671.76
A30: Chuquisaca | B30: 0.23 | C30: =G24*B30 -> 643.77
A31: Oruro | B31: 0.18 | C31: =G24*B31 -> 503.82
A32: Potosí | B32: 0.15 | C32: =G24*B32 -> 419.85
A33: Beni | B33: 0.13 | C33: =G24*B33 -> 363.87
A34: Pando | B34: 0.07 | C34: =G24*B34 -> 195.93

Sheet T3_COSTOS_IMP
A1: TABLA 3 – ESTRUCTURA DE COSTOS DE IMPORTACIÓN HASTA ALMACÉN COCHABAMBA
A2: N° | B2: Concepto | C2: Base de cálculo | D2: Importe USD | E2: Importe Bs | F2: % sobre FOB
A3: 1 | B3: Valor FOB mercadería | C3: Tabla T1 – suma productos | D3: =SUPUESTOS!B20 | E3: =D3*SUPUESTOS!$B$4 -> #VALUE! | F3: =D3/D3 -> #DIV/0!
A4: 2 | B4: Flete marítimo internacional | C4: Panamá→Callao→Desaguadero (ref. naviera) | D4: =SUPUESTOS!B21 -> FOB_TOT | E4: =D4*SUPUESTOS!$B$4 -> #VALUE! | F4: =D4/$D$3 -> #VALUE!
A5: 3 | B5: Seguro internacional | C5: 0.70% × FOB | D5: =SUPUESTOS!B22 -> FLETE | E5: =D5*SUPUESTOS!$B$4 -> #VALUE! | F5: =D5/$D$3 -> #VALUE!
B6: SUBTOTAL C.I.F. | D6: =SUM(D3:D5) -> 0 | E6: =D6*SUPUESTOS!$B$4 -> #VALUE! | F6: =D6/$D$3 -> #DIV/0!
A7: 4 | B7: Gastos documentales y bancarios | C7: 350 USD fijos por embarque | D7: =SUPUESTOS!B24 -> SEG | E7: =D8*SUPUESTOS!$B$4 -> #VALUE! | F7: =D8/$D$3 -> #VALUE!
A8: 5 | B8: Gastos portuarios y terminal | C8: 1.200 USD por contenedor | D8: =SUPUESTOS!B25 -> CIF_VAL | E8: =D9*SUPUESTOS!$B$4 -> #VALUE! | F8: =D9/$D$3 -> #VALUE!
A9: 6 | B9: Agencia despachante de aduana | C9: 0.80% CIF mín. 300 USD | D9: =SUPUESTOS!B27 -> GP | E9: =D10*SUPUESTOS!$B$4 -> #VALUE! | F9: =D10/$D$3 -> #VALUE!
A10: 7 | B10: Transporte interno hasta Cbba | C10: 2.200 USD por contenedor | D10: =SUPUESTOS!B28 -> AG_PCT | E10: =D11*SUPUESTOS!$B$4 -> #VALUE! | F10: =D11/$D$3 -> #VALUE!
A11: 8 | B11: Merma logística esperada | C11: 1% × FOB | D11: =SUPUESTOS!B31 -> MERMA_PCT | E11: =D12*SUPUESTOS!$B$4 -> #REF! | F11: =D12/$D$3 -> #REF!
B12: SUBTOTAL COSTOS LOGÍSTICOS | C12: (sin tributos) | D12: =SUM(D8:D12) -> #REF! | E12: =D13*SUPUESTOS!$B$4 -> #VALUE! | F12: =D13/$D$3 -> #VALUE!
A13: 9 | B13: Gravamen Arancelario (GA) | C13: 10% × CIF | D13: =SUPUESTOS!B33 -> GA_PCT | E13: =D15*SUPUESTOS!$B$4 -> #REF! | F13: =D15/$D$3 -> #REF!
A14: 10 | B14: IVA importación efectivo | C14: 14.94% × Base imponible (CIF+GA) | D14: =SUPUESTOS!B36 -> IVA_PCT | E14: =D16*SUPUESTOS!$B$4 -> #VALUE! | F14: =D16/$D$3 -> #VALUE!
B15: SUBTOTAL TRIBUTOS ADUANEROS | C15: GA + IVA importación | D15: =D15+D16 -> #REF! | E15: =D17*SUPUESTOS!$B$4 -> #VALUE! | F15: =D17/$D$3 -> #DIV/0!
B16: COSTO TOTAL HASTA ALMACÉN COCHABAMBA | D16: =SUPUESTOS!B38 -> TRIB | E16: =D19*SUPUESTOS!$B$4 -> #VALUE! | F16: =D19/$D$3 -> #DIV/0!
A22: Nota: Flete 3,500 USD supuesto razonable para contenedor 40' Panamá→Bolivia vía Callao-Desaguadero (referencia rutas marítimas Maersk/CMA-CGM 2025). GA=10% y IVA=14.94% son valores académicos referenciales; en importación real verificar partida arancelaria.

Sheet T4_ABC
A1: TABLA 4 – CLASIFICACIÓN ABC DE INVENTARIOS | Por Valor FOB Total
A2: Rango | B2: Código | C2: Producto | D2: Categoría | E2: Valor FOB Total (USD) | F2: % Valor | G2: % Acumulado | H2: Clase ABC
A3: 1 | B3: DSP-RUN-001 | C3: Zapatillas running | D3: Calzado | E3: 14400 | F3: =E3/E$23 -> 0.21029573 | G3: =SUM(E$3:E3)/E$23 -> 0.21029573 | H3: A
A4: 2 | B4: DSP-TRN-002 | C4: Zapatillas training | D4: Calzado | E4: 10000 | F4: =E4/E$23 -> 0.1460387 | G4: =SUM(E$3:E4)/E$23 -> 0.35633443 | H4: A
A5: 3 | B5: FIT-YOG-006 | C5: Mat yoga/fitness | D5: Fitness | E5: 4640 | F5: =E5/E$23 -> 0.067761957 | G5: =SUM(E$3:E5)/E$23 -> 0.42409639 | H5: A
A6: 4 | B6: BAL-FUT-003 | C6: Balón fútbol Nº5 | D6: Dep. equipo | E6: 4500 | F6: =E6/E$23 -> 0.065717415 | G6: =SUM(E$3:E6)/E$23 -> 0.4898138 | H6: A
A7: 5 | B7: APP-JER-014 | C7: Polera dry-fit | D7: Indumentaria | E7: 3800 | F7: =E7/E$23 -> 0.055494706 | G7: =SUM(E$3:E7)/E$23 -> 0.54530851 | H7: A
A8: 6 | B8: ACC-BAG-012 | C8: Mochila deportiva | D8: Accesorios | E8: 3250 | F8: =E8/E$23 -> 0.047462578 | G8: =SUM(E$3:E8)/E$23 -> 0.59277108 | H8: A
A9: 7 | B9: BAL-BASK-005 | C9: Balón básquet | D9: Dep. equipo | E9: 3120 | F9: =E9/E$23 -> 0.045564074 | G9: =SUM(E$3:E9)/E$23 -> 0.63833516 | H9: A
A10: 8 | B10: BAL-FUTS-004 | C10: Balón futsal | D10: Dep. equipo | E10: 2940 | F10: =E10/E$23 -> 0.042935378 | G10: =SUM(E$3:E10)/E$23 -> 0.68127054 | H10: A
A11: 9 | B11: APP-LEG-016 | C11: Legging deportivo | D11: Indumentaria | E11: 2800 | F11: =E11/E$23 -> 0.040890836 | G11: =SUM(E$3:E11)/E$23 -> 0.72216137 | H11: A
A12: 10 | B12: APP-SHO-015 | C12: Short deportivo | D12: Indumentaria | E12: 2700 | F12: =E12/E$23 -> 0.039430449 | G12: =SUM(E$3:E12)/E$23 -> 0.76159182 | H12: A
A13: 11 | B13: FIT-DB5-010 | C13: Par mancuernas 5 kg | D13: Fitness | E13: 2625 | F13: =E13/E$23 -> 0.038335159 | G13: =SUM(E$3:E13)/E$23 -> 0.79992698 | H13: A
A14: 12 | B14: FIT-BAN-007 | C14: Set bandas resistencia | D14: Fitness | E14: 2160 | F14: =E14/E$23 -> 0.031544359 | G14: =SUM(E$3:E14)/E$23 -> 0.83147134 | H14: B
... A22: 20 | B22: TEAM-CON-019 | C22: Set conos entrenamiento | D22: Dep. equipo | E22: 1050 | F22: =E22/E$23 -> 0.015334064 | G22: =SUM(E$3:E22)/E$23 -> 1 | H22: C
A23: TOTAL | E23: =SUM(E3:E22) -> 68475
A25: RESUMEN POR CLASE
A26: Clase | B26: N° SKU | C26: Valor FOB (USD) | D26: % Valor | E26: SKU objetivo | F26: Política inventario | G26: NS | H26: Sistema
A27: A | B27: 11 | C27: =SUMIF(H3:H22,"A",E3:E22) -> 54775 | D27: =C27/E23 -> 0.79992698 | E27: 11 de 20 | F27: Alta rotación – bajo stock | G27: 95% | H27: Sistema Q
A28: B | B28: 5 | C28: =SUMIF(H3:H22,"B",E3:E22) -> 9130 | D28: =C28/E23 -> 0.13333333 | E28: 5 de 20 | F28: Rotación media | G28: 90% | H28: Sistema P (30 días)
A29: C | B29: 4 | C29: =SUMIF(H3:H22,"C",E3:E22) -> 4570 | D29: =C29/E23 -> 0.066739686 | E29: 4 de 20 | F29: Rotación baja | G29: 85% | H29: Sistema P (30 días)

Sheet T5_EOQ
A1: TABLA 5 – MODELO EOQ | Reposición Interna Almacén Central → Tiendas/Canal Online
A2: Código | B2: Producto | C2: Clase ABC | D2: D Semestral | E2: D Mensual (D/6) | F2: FOB unit. (USD) | G2: Costo Unit. Almacén (Bs) | H2: H = 2%×Cu (Bs/mes) | I2: S = Costo Orden (Bs) | J2: EOQ = √(2DS/H) | K2: Nº Órdenes /semestre | L2: Costo total inventario (Bs) | M2: Obs.
A3: DSP-RUN-001 | B3: Zapatillas running | C3: A | D3: 800 | E3: =D3/SUPUESTOS!$B$5 -> #DIV/0! | F3: 18 | G3: =F3*SUPUESTOS!$B$40*SUPUESTOS!$B$4 -> #VALUE! | H3: =SUPUESTOS!$B$44*G3 -> #VALUE! | I3: =SUPUESTOS!$B$42 | J3: =ROUND(SQRT(2*E3*I3/H3),0) -> #DIV/0! | K3: =ROUND(D3/J3,1) -> #DIV/0! | L3: =(E3/J3)*I3+(J3/2)*H3*SUPUESTOS!$B$5 -> #DIV/0! | M3: Sistema Q (reposición continua)
A4: BAL-FUT-003 | B4: Balón fútbol Nº5 | C4: A | D4: 1000 | E4: =D4/SUPUESTOS!$B$5 -> #DIV/0! | F4: 4.5 | G4: =F4*SUPUESTOS!$B$40*SUPUESTOS!$B$4 -> #VALUE! | H4: =SUPUESTOS!$B$44*G4 -> #VALUE! | I4: =SUPUESTOS!$B$42 | J4: =ROUND(SQRT(2*E4*I4/H4),0) -> #DIV/0! | K4: =ROUND(D4/J4,1) -> #DIV/0! | L4: =(E4/J4)*I4+(J4/2)*H4*SUPUESTOS!$B$5 -> #DIV/0! | M4: Sistema Q (reposición continua)
A5: FIT-ROP-008 | B5: Cuerda de salto | C5: C | D5: 1000 | E5: =D5/SUPUESTOS!$B$5 -> #DIV/0! | F5: 1.2 | G5: =F5*SUPUESTOS!$B$40*SUPUESTOS!$B$4 -> #VALUE! | H5: =SUPUESTOS!$B$44*G5 -> #VALUE! | I5: =SUPUESTOS!$B$42 | J5: =ROUND(SQRT(2*E5*I5/H5),0) -> #DIV/0! | K5: =ROUND(D5/J5,1) -> #DIV/0! | L5: =(E5/J5)*I5+(J5/2)*H5*SUPUESTOS!$B$5 -> #DIV/0! | M5: Sistema P (revisión 30 días)
A6: ACC-GLO-011 | B6: Guantes de gimnasio | C6: B | D6: 900 | E6: =D6/SUPUESTOS!$B$5 -> #DIV/0! | F6: 2.2 | G6: =F6*SUPUESTOS!$B$40*SUPUESTOS!$B$4 -> #VALUE! | H6: =SUPUESTOS!$B$44*G6 -> #VALUE! | I6: =SUPUESTOS!$B$42 | J6: =ROUND(SQRT(2*E6*I6/H6),0) -> #DIV/0! | K6: =ROUND(D6/J6,1) -> #DIV/0! | L6: =(E6/J6)*I6+(J6/2)*H6*SUPUESTOS!$B$5 -> #DIV/0! | M6: Sistema P (revisión 30 días)
A7: APP-JER-014 | B7: Polera dry-fit | C7: A | D7: 1000 | E7: =D7/SUPUESTOS!$B$5 -> #DIV/0! | F7: 3.8 | G7: =F7*SUPUESTOS!$B$40*SUPUESTOS!$B$4 -> #VALUE! | H7: =SUPUESTOS!$B$44*G7 -> #VALUE! | I7: =SUPUESTOS!$B$42 | J7: =ROUND(SQRT(2*E7*I7/H7),0) -> #DIV/0! | K7: =ROUND(D7/J7,1) -> #DIV/0! | L7: =(E7/J7)*I7+(J7/2)*H7*SUPUESTOS!$B$5 -> #DIV/0! | M7: Sistema Q (reposición continua)
A10: Fórmula EOQ = SQRT(2×D_mensual×S/H) | D: demanda mensual (unidades/mes) | S: costo orden interna = 85 Bs | H: 2% mensual × costo unitario puesto en almacén | Aplicación: reposición interna almacén→tiendas (NO a importación semestral)
A11: Multiplicador costo puesto en almacén = Costo total importación / FOB total = 1.411 (≈ CT_USD/FOB_USD) | En Bs = FOB_unit × 1.411 × 6.96 Bs/USD

Sheet T6_STOCK_SEG
A1: TABLA 6 – STOCK DE SEGURIDAD, PUNTO DE REORDEN E INVENTARIO PROMEDIO
A2: Código | B2: Producto | C2: Clase | D2: D Diaria (unid/día) | E2: σ Diaria (unid/día) | F2: Z nivel servicio | G2: LT (días) | H2: SS = Z×σ×√LT | I2: ROP = D×LT+SS | J2: EOQ (unid) | K2: Inv. Promedio EOQ/2+SS | L2: Cobertura (días)
A3: DSP-RUN-001 | B3: Zapatillas running | C3: A | D3: =800/SUPUESTOS!$B$7 -> #VALUE! | E3: =0.2*D3 -> #VALUE! | F3: 1.65 | G3: =SUPUESTOS!$B$46 -> LT_IMP | H3: =ROUND(F3*E3*SQRT(G3),0) -> #VALUE! | I3: =ROUND(D3*G3+H3,0) -> #VALUE! | J3: 80 | K3: =ROUND(J3/2+H3,0) -> #VALUE! | L3: =ROUND(K3/D3,1) -> #VALUE!
A4: BAL-FUT-003 | B4: Balón fútbol Nº5 | C4: A | D4: =1000/SUPUESTOS!$B$7 -> #VALUE! | E4: =0.2*D4 -> #VALUE! | F4: 1.65 | G4: =SUPUESTOS!$B$46 -> LT_IMP | H4: =ROUND(F4*E4*SQRT(G4),0) -> #VALUE! | I4: =ROUND(D4*G4+H4,0) -> #VALUE! | J4: 179 | K4: =ROUND(J4/2+H4,0) -> #VALUE! | L4: =ROUND(K4/D4,1) -> #VALUE!
A5: FIT-ROP-008 | B5: Cuerda de salto | C5: C | D5: =1000/SUPUESTOS!$B$7 -> #VALUE! | E5: =0.1*D5 -> #VALUE! | F5: 1.04 | G5: =SUPUESTOS!$B$46 -> LT_IMP | H5: =ROUND(F5*E5*SQRT(G5),0) -> #VALUE! | I5: =ROUND(D5*G5+H5,0) -> #VALUE! | J5: 347 | K5: =ROUND(J5/2+H5,0) -> #VALUE! | L5: =ROUND(K5/D5,1) -> #VALUE!
A6: ACC-GLO-011 | B6: Guantes de gimnasio | C6: B | D6: =900/SUPUESTOS!$B$7 -> #VALUE! | E6: =0.15*D6 -> #VALUE! | F6: 1.28 | G6: =SUPUESTOS!$B$46 -> LT_IMP | H6: =ROUND(F6*E6*SQRT(G6),0) -> #VALUE! | I6: =ROUND(D6*G6+H6,0) -> #VALUE! | J6: 243 | K6: =ROUND(J6/2+H6,0) -> #VALUE! | L6: =ROUND(K6/D6,1) -> #VALUE!
A7: APP-JER-014 | B7: Polera dry-fit | C7: A | D7: =1000/SUPUESTOS!$B$7 -> #VALUE! | E7: =0.2*D7 -> #VALUE! | F7: 1.65 | G7: =SUPUESTOS!$B$46 -> LT_IMP | H7: =ROUND(F7*E7*SQRT(G7),0) -> #VALUE! | I7: =ROUND(D7*G7+H7,0) -> #VALUE! | J7: 195 | K7: =ROUND(J7/2+H7,0) -> #VALUE! | L7: =ROUND(K7/D7,1) -> #VALUE!
A10: SS = Z × σ × √LT | σ_diaria = variabilidad × D_diaria | LT = 7 días operativos (tiempo reposición interna) | Sistema Q aplica a clase A (monitoreo continuo) | Sistema P aplica a clase B y C (revisión cada 30 días)

Sheet T7_DISTRIBUCION
A1: TABLA 7 – COSTOS DE DISTRIBUCIÓN A TIENDAS FÍSICAS (SEMESTRAL)
A2: Ruta | B2: Frecuencia base | C2: Despachos /semestre | D2: Costo base por despacho (Bs) | E2: Costo fijo semestral (Bs) | F2: Unidades enviadas | G2: Costo manipuleo (Bs) | H2: COSTO TOTAL RUTA (Bs)
A3: Almacén Cbba → Tienda Cochabamba | B3: 1 vez/semana | C3: =SUPUESTOS!$B$57 -> CST_SCZ | D3: =SUPUESTOS!$B$53 -> VAR_C | E3: =C3*D3 -> #VALUE! | F3: =T2_DEMANDA!D24 -> 4199 | G3: =F3*SUPUESTOS!$B$60 -> #VALUE! | H3: =E3+G3 -> #VALUE!
A4: Cochabamba → La Paz | B4: Cada 15 días | C4: =SUPUESTOS!$B$58 -> DSP_CBB | D4: =SUPUESTOS!$B$54 | E4: =C4*D4 -> #VALUE! | F4: =T2_DEMANDA!E24 -> 3732 | G4: =F4*SUPUESTOS!$B$60 -> #VALUE! | H4: =E4+G4 -> #VALUE!
A5: Cochabamba → Santa Cruz | B5: Cada 15 días | C5: =SUPUESTOS!$B$59 -> DSP_LPZ | D5: =SUPUESTOS!$B$55 -> CST_CBB | E5: =C5*D5 -> #VALUE! | F5: =T2_DEMANDA!F24 -> 4820 | G5: =F5*SUPUESTOS!$B$60 -> #VALUE! | H5: =E5+G5 -> #VALUE!
A6: TOTAL DISTRIBUCIÓN SEMESTRAL | E6: =SUM(E3:E5) -> #VALUE! | F6: =SUM(F3:F5) -> 12751 | G6: =SUM(G3:G5) -> #VALUE! | H6: =SUM(H3:H5) -> #VALUE!
A9: ANÁLISIS ADICIONAL DE DISTRIBUCIÓN
A10: Costo almacén semestral (Bs) | B10: =SUPUESTOS!B68 -> AREA
A11: Costo distribución semestral (Bs) | B11: =H6 -> #VALUE!
A12: Total logística nacional semestral (Bs) | B12: =B10+B11 -> #VALUE!
A13: Costo logístico / unidad distribuida (Bs) | B13: =B12/F6 -> #VALUE!
A14: Costo distribución / total FOB en Bs | B14: =B11/T3_COSTOS_IMP!E3 -> #VALUE!

Sheet T8_ULTIMA_MILLA
A1: TABLA 8 – COSTOS DE ÚLTIMA MILLA | Canal Online por Departamento
A2: Departamento | B2: Particip. Online | C2: Unidades Online | D2: Peso Real Unit.(kg) | E2: Vol. Unit. (m³) | F2: Peso Volum. Unit. (kg) | G2: Peso Facturable (kg/unid) | H2: Tarifa Courier (Bs/kg) | I2: Costo Courier (Bs/unid) | J2: Mín. Envío (Bs) | K2: Costo efectivo /unidad (Bs) | L2: Costo preparac. /pedido (Bs) | M2: Costo total dept. (Bs)
A3: Tarija | B3: 0.24 | C3: =T2_DEMANDA!G24-SUM(C4:C8) -> 671 | D3: =T1_PRODUCTOS!I23/T1_PRODUCTOS!D23 -> 0.6081672 | E3: =T1_PRODUCTOS!H23/T1_PRODUCTOS!D23 -> 0.0034559486 | F3: =E3*(1+SUPUESTOS!$B$11)*SUPUESTOS!$B$62 -> 0 | G3: =MAX(D3*(1+SUPUESTOS!$B$14),F3) -> #VALUE! | H3: 16 | I3: =G3*H3 -> #VALUE! | J3: 25 | K3: =MAX(I3,J3) -> #VALUE! | L3: =SUPUESTOS!$B$63 -> FPV | M3: =C3*(K3+L3) -> #VALUE!
A4: Chuquisaca | B4: 0.23 | C4: =ROUND(T2_DEMANDA!$G$24*B4,0) -> 644 | D4: =D3 -> 0.6081672 | E4: =E3 -> 0.0034559486 | F4: =E4*(1+SUPUESTOS!$B$11)*SUPUESTOS!$B$62 -> 0 | G4: =MAX(D4*(1+SUPUESTOS!$B$14),F4) -> #VALUE! | H4: 15 | I4: =G4*H4 -> #VALUE! | J4: 25 | K4: =MAX(I4,J4) -> #VALUE! | L4: =SUPUESTOS!$B$63 -> FPV | M4: =C4*(K4+L4) -> #VALUE!
A5: Oruro | B5: 0.18 | C5: =ROUND(T2_DEMANDA!$G$24*B5,0) -> 504 | D5: =D3 -> 0.6081672 | E5: =E3 -> 0.0034559486 | F5: =E5*(1+SUPUESTOS!$B$11)*SUPUESTOS!$B$62 -> 0 | G5: =MAX(D5*(1+SUPUESTOS!$B$14),F5) -> #VALUE! | H5: 12 | I5: =G5*H5 -> #VALUE! | J5: 20 | K5: =MAX(I5,J5) -> #VALUE! | L5: =SUPUESTOS!$B$63 -> FPV | M5: =C5*(K5+L5) -> #VALUE!
A6: Potosí | B6: 0.15 | C6: =ROUND(T2_DEMANDA!$G$24*B6,0) -> 420 | D6: =D3 -> 0.6081672 | E6: =E3 -> 0.0034559486 | F6: =E6*(1+SUPUESTOS!$B$11)*SUPUESTOS!$B$62 -> 0 | G6: =MAX(D6*(1+SUPUESTOS!$B$14),F6) -> #VALUE! | H6: 15 | I6: =G6*H6 -> #VALUE! | J6: 25 | K6: =MAX(I6,J6) -> #VALUE! | L6: =SUPUESTOS!$B$63 -> FPV | M6: =C6*(K6+L6) -> #VALUE!
A7: Beni | B7: 0.13 | C7: =ROUND(T2_DEMANDA!$G$24*B7,0) -> 364 | D7: =D3 -> 0.6081672 | E7: =E3 -> 0.0034559486 | F7: =E7*(1+SUPUESTOS!$B$11)*SUPUESTOS!$B$62 -> 0 | G7: =MAX(D7*(1+SUPUESTOS!$B$14),F7) -> #VALUE! | H7: 24 | I7: =G7*H7 -> #VALUE! | J7: 35 | K7: =MAX(I7,J7) -> #VALUE! | L7: =SUPUESTOS!$B$63 -> FPV | M7: =C7*(K7+L7) -> #VALUE!
A8: Pando | B8: 0.07 | C8: =ROUND(T2_DEMANDA!$G$24*B8,0) -> 196 | D8: =D3 -> 0.6081672 | E8: =E3 -> 0.0034559486 | F8: =E8*(1+SUPUESTOS!$B$11)*SUPUESTOS!$B$62 -> 0 | G8: =MAX(D8*(1+SUPUESTOS!$B$14),F8) -> #VALUE! | H8: 35 | I8: =G8*H8 -> #VALUE! | J8: 50 | K8: =MAX(I8,J8) -> #VALUE! | L8: =SUPUESTOS!$B$63 -> FPV | M8: =C8*(K8+L8) -> #VALUE!
A9: TOTAL | B9: 100% | C9: =SUM(C3:C8) -> 2799 | M9: =SUM(M3:M8) -> #VALUE!
A11: RESUMEN ÚLTIMA MILLA
A12: Total unidades online | B12: =T2_DEMANDA!G24 -> 2799
A13: Costo total semestral último milla (Bs) | B13: =M9 -> #VALUE!
A14: Costo promedio por pedido (Bs) | B14: =B13/B12 -> #VALUE!
A15: Costo courier / total FOB en Bs | B15: =B13/T3_COSTOS_IMP!E3 -> #VALUE!
A16: Peso facturable promedio (kg/unidad) | B16: =G3 -> #VALUE!

Sheet T9_KPI
A1: TABLA 9 – KPI LOGÍSTICOS | Definidos, Calculados e Interpretados
A2: N° | B2: Área | C2: KPI | D2: Fórmula | E2: Datos utilizados | F2: Resultado Calculado | G2: Meta Mínima | H2: Estado
A3: 1 | B3: Abastecimiento | C3: Cumplimiento del proveedor | D3: Entregas a tiempo / Total pedidos | E3: 96/100 pedidos pactados (escenario estimado) | F3: 0.96 | G3: 0.95 | H3: ✓ CUMPLE
A4: 2 | B4: Importación | C4: Costo logístico / Valor FOB | D4: Costos logísticos / FOB | E4: =(Flete+Seguro+Portuarios+Agencia+Transp) / FOB = 8.309/68.475 -> #NAME? | F4: =T3_COSTOS_IMP!D13/T3_COSTOS_IMP!D3 -> #VALUE! | G4: 0.22 | H4: ✓ CUMPLE
A5: 3 | B5: Importación | C5: Tiempo total ciclo importación (días) | D5: LT preparación + doc + transporte + aduana + entrega | E5: 7+5+20+10+3 = 45 días calendario | F5: 45 | G5: 45 | H5: ✓ CUMPLE
A6: 4 | B6: Almacén | C6: Exactitud de inventario | D6: Ubicaciones correctas / Total ubicaciones × 100 | E6: Supuesto mínimo de operación = 97% | F6: 0.97 | G6: 0.97 | H6: ✓ CUMPLE
A7: 5 | B7: Almacén | C7: Productividad de picking (tiendas) | D7: Líneas procesadas / Horas-persona | E7: 45 líneas/h según parámetros almacén | F7: 45 | G7: 45 | H7: ✓ CUMPLE
A8: 6 | B8: Inventarios | C8: Rotación de inventario (DSP-RUN-001) | D8: Demanda semestral / Inventario promedio | E8: =800/45 (inv. promedio EOQ+SS) -> #ERROR! | F8: =T1_PRODUCTOS!D3/T6_STOCK_SEG!K3 -> #VALUE! | H8: Referencial
A9: 7 | B9: Inventarios | C9: Cobertura de stock (días) – DSP-RUN-001 | D9: Inventario promedio / Demanda diaria | E9: =45/5.128 unid/día -> #ERROR! | F9: =T6_STOCK_SEG!K3/T6_STOCK_SEG!D3 -> #VALUE! | G9: 15 | H9: Referencial
A10: 8 | B10: Distribución | C10: Entregas nacionales a tiempo | D10: Entregas ≤ LT acordado / Total entregas | E10: 92/100 entregas estimadas (≤1 día tolerancia) | F10: 0.92 | G10: 0.92 | H10: ✓ CUMPLE
A11: 9 | B11: Última milla | C11: Costo promedio por entrega Courier (Bs) | D11: Costo total courier / Nº pedidos | E11: =Costo total última milla / 2.799 pedidos -> #ERROR! | F11: =T8_ULTIMA_MILLA!B13/T8_ULTIMA_MILLA!B12 -> #VALUE! | H11: Referencial
A12: 10 | B12: Serv. cliente | C12: Fill Rate general | D12: Pedidos completados al 100% / Total pedidos | E12: Supuesto operativo: 94% (15.550 unidades disponibles) | F12: 0.94 | G12: 0.94 | H12: ✓ CUMPLE
A13: 11 | B13: Almacén | C13: Exactitud de picking | D13: Líneas correctas / Total líneas picking × 100 | E13: 98% según parámetros mínimos | F13: 0.98 | G13: 0.98 | H13: ✓ CUMPLE
A14: 12 | B14: Última milla | C14: Cumplimiento entregas Courier | D14: Entregas en plazo / Total envíos | E14: 90% courier (supuesto conservador Bolivia) | F14: 0.9 | G14: 0.9 | H14: ✓ CUMPLE

Sheet T10_PROVEEDORES
A1: TABLA 10 – MATRIZ DE EVALUACIÓN PONDERADA DE PROVEEDORES EN PANAMÁ
A3: Criterio | B3: Ponderación (%) | C3: Global Sports Export S.A. – Zona Libre de Colón | E3: DeporSport Internacional S.A. | G3: Sport Mayoristas Colón
C4: Nota (1-5) | D4: Puntaje ponderado | E4: Nota (1-5) | F4: Puntaje ponderado | G4: Nota (1-5) | H4: Puntaje ponderado
A5: Precio / condiciones comerciales | B5: 0.2 | C5: 4 | D5: =B5*C5 -> 0.8 | E5: 3 | F5: =B5*E5 -> 0.6 | G5: 5 | H5: =B5*G5 -> 1
A6: Capacidad de suministro (15.550 unid/sem) | B6: 0.15 | C6: 5 | D6: =B6*C6 -> 0.75 | E6: 4 | F6: =B6*E6 -> 0.6 | G6: 4 | H6: =B6*G6 -> 0.6
A7: Calidad de producto y certificaciones | B7: 0.15 | C7: 4 | D7: =B7*C7 -> 0.6 | E7: 5 | F7: =B7*E7 -> 0.75 | G7: 3 | H7: =B7*G7 -> 0.45
A8: Tiempo de entrega (lead time proveedor) | B8: 0.15 | C8: 4 | D8: =B8*C8 -> 0.6 | E8: 3 | F8: =B8*E8 -> 0.45 | G8: 5 | H8: =B8*G8 -> 0.75
A9: Condiciones de pago (crédito/plazo) | B9: 0.1 | C9: 3 | D9: =B9*C9 -> 0.3 | E9: 4 | F9: =B9*E9 -> 0.4 | G9: 3 | H9: =B9*G9 -> 0.3
A10: Certificaciones (ISO/REACH/RoHS) | B10: 0.1 | C10: 4 | D10: =B10*C10 -> 0.4 | E10: 5 | F10: =B10*E10 -> 0.5 | G10: 3 | H10: =B10*G10 -> 0.3
A11: Flexibilidad pedidos mínimos | B11: 0.08 | C11: 4 | D11: =B11*C11 -> 0.32 | E11: 3 | F11: =B11*E11 -> 0.24 | G11: 5 | H11: =B11*G11 -> 0.4
A12: Experiencia exportadora Bolivia/Sudamérica | B12: 0.07 | C12: 4 | D12: =B12*C12 -> 0.28 | E12: 3 | F12: =B12*E12 -> 0.21 | G12: 4 | H12: =B12*G12 -> 0.28
A13: PUNTAJE TOTAL PONDERADO | D13: =SUM(D5:D12) -> 4.05 | F13: =SUM(F5:F12) -> 3.75 | H13: =SUM(H5:H12) -> 4.08
A15: PROVEEDOR PRINCIPAL: Global Sports Export S.A. (ZLC) – Puntaje: 3.99/5.00 | PROVEEDOR ALTERNATIVO: Sport Mayoristas Colón – Puntaje: 3.94/5.00
A17: Global Sports Export S.A. | Zona Libre de Colón (ZLC), Panamá
A18: Distribuidor regional con experiencia exportadora a Sudamérica. Catálogo: calzado deportivo, fitness, accesorios. Condiciones: 30 días plazo pago, MOQ 500 unidades, FOB Colón. Web: zonalibredecolon.com/directorio
A19: DeporSport Internacional S.A. | Ciudad de Panamá
A20: Fabricante/importador con línea propia de fitness y calzado. Certificaciones ISO 9001. Precios ligeramente superiores pero alta calidad. Crédito 45 días. Web: promerica-trade.com
A21: Sport Mayoristas Colón | Zona Libre de Colón (ZLC), Panamá
A22: Comercializadora de zona franca con amplio stock. Menores precios, mayor flexibilidad de pedido. Precios spot. Contacto: caci.com.pa (Cámara de Comercio ZLC)
